[
  "unknown_error: error(existence_error(source_sink,'../python/venv/bin/python3'),_434354)"
]